Workbook

Sheet README
A1: Shopee Affiliate — Product Vetting Scorecard & Tracker
A2: Built to your spec. Fill the yellow cells; grey cells calculate themselves.
A4: HOW TO USE
A5: 1. Research on Shopee yourself (or export from your Affiliate dashboard). This file does not pull live data.
A6: 2. Paste one product per row into the Tracker tab, columns A-X (yellow).
A7: 3. Column Y auto-runs the HARD GATES. 'FAIL' means the product breaks one of your minimums - drop it.
A8: 4. Columns Z-AK auto-score every product out of 100 and rank the survivors.
A9: 5. Write your listing copy on the Content tab. Product names pull across automatically.
A10: 6. Collections tab shows a live count per collection so you can see which ones are thin.
A12: THE FIVE HARD GATES (all must pass)
A13: Units sold >= 5,000 | Rating >= 4.8 | Reviews >= 500 | In stock = Yes | Seller is Mall / Preferred Plus / Preferred
A14: Change any threshold on the Rubric tab and every row re-scores instantly.
... A38: Any product whose gate flips to FAIL, or whose score drops below 65, should come off the store.

Sheet Rubric
A1: Scoring Rubric — every number below is editable
A3: SECTION 1 — HARD GATES (fail any one and the product is rejected)
A4: Criterion | B4: Threshold | C4: Points
A5: Minimum units sold | B5: 5000
A6: Minimum star rating | B6: 4.8
A7: Minimum number of reviews | B7: 500
A8: Must be in stock | B8: Yes
A9: Seller must be one of | B9: Shopee Mall / Preferred Plus / Preferred
A11: SECTION 2 — WEIGHT OF EACH COMPONENT (reference only)
A12: Component | C12: Max Points
A13: Sales volume | C13: 25
A14: Star rating | C14: 15
A15: Seller type | C15: 15
A16: Number of reviews | C16: 10
A17: Discount depth | C17: 10
A18: Promo stack | C18: 10
A19: Value for money | C19: 10
A20: Store rating | C20: 5
A21: TOTAL | C21: =SUM(C13:C20) -> 100
A23: SECTION 3 — TIER TABLES (thresholds must stay in ascending order)
A24: Sales volume — units sold
B25: At least | C25: Points
B26: 0 | C26: 0
B27: 5000 | C27: 12
B28: 10000 | C28: 17
B29: 25000 | C29: 21
B30: 50000 | C30: 25
A32: Star rating
B33: At least | C33: Points
B34: 0 | C34: 0
B35: 4.8 | C35: 9
B36: 4.85 | C36: 12
B37: 4.9 | C37: 15
A39: Number of reviews
B40: At least | C40: Points
B41: 0 | C41: 0
B42: 500 | C42: 5
B43: 1000 | C43: 7
B44: 5000 | C44: 9
B45: 10000 | C45: 10
...

Sheet Tracker
A1: Product Tracker — paste research into the yellow columns (A–X); grey columns (Y–AK) calculate
A2: YOUR RESEARCH → columns A to X | Y2: AUTO-SCORING → columns Y to AK
A3: Product Name | B3: Product Link | C3: Affiliate Link | D3: Category | E3: Subcategory | F3: Brand | G3: Current Price | H3: Original Price | I3: Discount % | J3: Units Sold | K3: Rating | L3: Reviews | M3: Seller Name | N3: Seller Type | O3: Store Rating | P3: Has Voucher | Q3: Promo Type | R3: Free Shipping | S3: In Stock | T3: Stock Risk | U3: Recent Neg. Reviews | V3: Value for Money 1-5 | W3: Key Features | X3: Main Benefits | Y3: GATE | Z3: Sales pts | AA3: Rating pts | AB3: Review pts | AC3: Seller pts | AD3: Store pts | AE3: Discount pts | AF3: Promo pts | AG3: Value pts | AH3: Risk deduct | AI3: TOTAL SCORE | AJ3: Priority Tier | AK3: Rank
A4: [EXAMPLE — delete this row] 20W USB-C Fast Charger | B4: https://shopee.ph/product/000000000/0000000000 | C4: https://s.shopee.ph/XXXXXXXX | D4: Electronics | E4: Chargers | F4: Sample Brand | G4: 249 | H4: 499 | I4: =IF($A4="","",IF($H4=0,0,1-$G4/$H4)) -> 0.501002 | J4: 18500 | K4: 4.9 | L4: 3200 | M4: Sample Official Store | N4: Shopee Mall | O4: 4.9 | P4: Yes | Q4: Discount only | R4: Yes | S4: Yes | T4: No | U4: No | V4: 5 | W4: 20W PD output; USB-C port; over-current protection; compact body | X4: Charges a phone to ~50% in about 30 min; small enough for a pocket | Y4: =IF($A4="","",IF(AND($J4>=Rubric!$B$5,$K4>=Rubric!$B$6,$L4>=Rubric!$B$7,$S4=Rubric!$B$8,OR($N4="Shopee Mall",$N4="Preferred Plus",$N4="Preferred")),"PASS","FAIL")) -> PASS | Z4: {=IF($A4="","",IFERROR(INDEX(Rubric!$C$26:$C$30,MATCH($J4,Rubric!$B$26:$B$30,1)),0))} -> 17 | AA4: {=IF($A4="","",IFERROR(INDEX(Rubric!$C$34:$C$37,MATCH($K4,Rubric!$B$34:$B$37,1)),0))} -> 15 | AB4: {=IF($A4="","",IFERROR(INDEX(Rubric!$C$41:$C$45,MATCH($L4,Rubric!$B$41:$B$45,1)),0))} -> 7 | AC4: {=IF($A4="","",IFERROR(INDEX(Rubric!$C$49:$C$52,MATCH($N4,Rubric!$B$49:$B$52,0)),0))} -> 15 | AD4: {=IF($A4="","",IFERROR(INDEX(Rubric!$C$56:$C$59,MATCH($O4,Rubric!$B$56:$B$59,1)),0))} -> 5 | AE4: {=IF($A4="","",IFERROR(INDEX(Rubric!$C$63:$C$67,MATCH($I4,Rubric!$B$63:$B$67,1)),0))} -> 10 | AF4: =IF($A4="","",IF($P4="Yes",Rubric!$C$71,0)+IF($R4="Yes",Rubric!$C$72,0)+IF($Q4="Buy 1 Take 1 or better",Rubric!$C$73,0)) -> 6 | AG4: =IF($A4="","",IFERROR($V4*Rubric!$C$77,0)) -> 10 | AH4: =IF($A4="","",IF($T4="Yes",Rubric!$C$81,0)+IF($U4="Yes",Rubric!$C$82,0)) -> 0 | AI4: =IF($A4="","",IF($Y4="FAIL",0,MAX(0,SUM($Z4:$AG4)+$AH4))) -> 85 | AJ4: {=IF($A4="","",IF($Y4="FAIL","Rejected — failed gate",IFERROR(INDEX(Rubric!$C$86:$C$89,MATCH($AI4,Rubric!$B$86:$B$89,1)),"")))} -> Tier A — Feature | AK4: =IF($Y4<>"PASS","",COUNTIFS($Y$4:$Y$63,"PASS",$AI$4:$AI$63,">"&$AI4)+1) -> 1
I5: =IF($A5="","",IF($H5=0,0,1-$G5/$H5)) | Y5: =IF($A5="","",IF(AND($J5>=Rubric!$B$5,$K5>=Rubric!$B$6,$L5>=Rubric!$B$7,$S5=Rubric!$B$8,OR($N5="Shopee Mall",$N5="Preferred Plus",$N5="Preferred")),"PASS","FAIL")) | Z5: {=IF($A5="","",IFERROR(INDEX(Rubric!$C$26:$C$30,MATCH($J5,Rubric!$B$26:$B$30,1)),0))} | AA5: {=IF($A5="","",IFERROR(INDEX(Rubric!$C$34:$C$37,MATCH($K5,Rubric!$B$34:$B$37,1)),0))} | AB5: {=IF($A5="","",IFERROR(INDEX(Rubric!$C$41:$C$45,MATCH($L5,Rubric!$B$41:$B$45,1)),0))} | AC5: {=IF($A5="","",IFERROR(INDEX(Rubric!$C$49:$C$52,MATCH($N5,Rubric!$B$49:$B$52,0)),0))} | AD5: {=IF($A5="","",IFERROR(INDEX(Rubric!$C$56:$C$59,MATCH($O5,Rubric!$B$56:$B$59,1)),0))} | AE5: {=IF($A5="","",IFERROR(INDEX(Rubric!$C$63:$C$67,MATCH($I5,Rubric!$B$63:$B$67,1)),0))} | AF5: =IF($A5="","",IF($P5="Yes",Rubric!$C$71,0)+IF($R5="Yes",Rubric!$C$72,0)+IF($Q5="Buy 1 Take 1 or better",Rubric!$C$73,0)) | AG5: =IF($A5="","",IFERROR($V5*Rubric!$C$77,0)) | AH5: =IF($A5="","",IF($T5="Yes",Rubric!$C$81,0)+IF($U5="Yes",Rubric!$C$82,0)) | AI5: =IF($A5="","",IF($Y5="FAIL",0,MAX(0,SUM($Z5:$AG5)+$AH5))) | AJ5: {=IF($A5="","",IF($Y5="FAIL","Rejected — failed gate",IFERROR(INDEX(Rubric!$C$86:$C$89,MATCH($AI5,Rubric!$B$86:$B$89,1)),"")))} | AK5: =IF($Y5<>"PASS","",COUNTIFS($Y$4:$Y$63,"PASS",$AI$4:$AI$63,">"&$AI5)+1)
I6: =IF($A6="","",IF($H6=0,0,1-$G6/$H6)) | Y6: =IF($A6="","",IF(AND($J6>=Rubric!$B$5,$K6>=Rubric!$B$6,$L6>=Rubric!$B$7,$S6=Rubric!$B$8,OR($N6="Shopee Mall",$N6="Preferred Plus",$N6="Preferred")),"PASS","FAIL")) | Z6: {=IF($A6="","",IFERROR(INDEX(Rubric!$C$26:$C$30,MATCH($J6,Rubric!$B$26:$B$30,1)),0))} | AA6: {=IF($A6="","",IFERROR(INDEX(Rubric!$C$34:$C$37,MATCH($K6,Rubric!$B$34:$B$37,1)),0))} | AB6: {=IF($A6="","",IFERROR(INDEX(Rubric!$C$41:$C$45,MATCH($L6,Rubric!$B$41:$B$45,1)),0))} | AC6: {=IF($A6="","",IFERROR(INDEX(Rubric!$C$49:$C$52,MATCH($N6,Rubric!$B$49:$B$52,0)),0))} | AD6: {=IF($A6="","",IFERROR(INDEX(Rubric!$C$56:$C$59,MATCH($O6,Rubric!$B$56:$B$59,1)),0))} | AE6: {=IF($A6="","",IFERROR(INDEX(Rubric!$C$63:$C$67,MATCH($I6,Rubric!$B$63:$B$67,1)),0))} | AF6: =IF($A6="","",IF($P6="Yes",Rubric!$C$71,0)+IF($R6="Yes",Rubric!$C$72,0)+IF($Q6="Buy 1 Take 1 or better",Rubric!$C$73,0)) | AG6: =IF($A6="","",IFERROR($V6*Rubric!$C$77,0)) | AH6: =IF($A6="","",IF($T6="Yes",Rubric!$C$81,0)+IF($U6="Yes",Rubric!$C$82,0)) | AI6: =IF($A6="","",IF($Y6="FAIL",0,MAX(0,SUM($Z6:$AG6)+$AH6))) | AJ6: {=IF($A6="","",IF($Y6="FAIL","Rejected — failed gate",IFERROR(INDEX(Rubric!$C$86:$C$89,MATCH($AI6,Rubric!$B$86:$B$89,1)),"")))} | AK6: =IF($Y6<>"PASS","",COUNTIFS($Y$4:$Y$63,"PASS",$AI$4:$AI$63,">"&$AI6)+1)
I7: =IF($A7="","",IF($H7=0,0,1-$G7/$H7)) | Y7: =IF($A7="","",IF(AND($J7>=Rubric!$B$5,$K7>=Rubric!$B$6,$L7>=Rubric!$B$7,$S7=Rubric!$B$8,OR($N7="Shopee Mall",$N7="Preferred Plus",$N7="Preferred")),"PASS","FAIL")) | Z7: {=IF($A7="","",IFERROR(INDEX(Rubric!$C$26:$C$30,MATCH($J7,Rubric!$B$26:$B$30,1)),0))} | AA7: {=IF($A7="","",IFERROR(INDEX(Rubric!$C$34:$C$37,MATCH($K7,Rubric!$B$34:$B$37,1)),0))} | AB7: {=IF($A7="","",IFERROR(INDEX(Rubric!$C$41:$C$45,MATCH($L7,Rubric!$B$41:$B$45,1)),0))} | AC7: {=IF($A7="","",IFERROR(INDEX(Rubric!$C$49:$C$52,MATCH($N7,Rubric!$B$49:$B$52,0)),0))} | AD7: {=IF($A7="","",IFERROR(INDEX(Rubric!$C$56:$C$59,MATCH($O7,Rubric!$B$56:$B$59,1)),0))} | AE7: {=IF($A7="","",IFERROR(INDEX(Rubric!$C$63:$C$67,MATCH($I7,Rubric!$B$63:$B$67,1)),0))} | AF7: =IF($A7="","",IF($P7="Yes",Rubric!$C$71,0)+IF($R7="Yes",Rubric!$C$72,0)+IF($Q7="Buy 1 Take 1 or better",Rubric!$C$73,0)) | AG7: =IF($A7="","",IFERROR($V7*Rubric!$C$77,0)) | AH7: =IF($A7="","",IF($T7="Yes",Rubric!$C$81,0)+IF($U7="Yes",Rubric!$C$82,0)) | AI7: =IF($A7="","",IF($Y7="FAIL",0,MAX(0,SUM($Z7:$AG7)+$AH7))) | AJ7: {=IF($A7="","",IF($Y7="FAIL","Rejected — failed gate",IFERROR(INDEX(Rubric!$C$86:$C$89,MATCH($AI7,Rubric!$B$86:$B$89,1)),"")))} | AK7: =IF($Y7<>"PASS","",COUNTIFS($Y$4:$Y$63,"PASS",$AI$4:$AI$63,">"&$AI7)+1)
I8: =IF($A8="","",IF($H8=0,0,1-$G8/$H8)) | Y8: =IF($A8="","",IF(AND($J8>=Rubric!$B$5,$K8>=Rubric!$B$6,$L8>=Rubric!$B$7,$S8=Rubric!$B$8,OR($N8="Shopee Mall",$N8="Preferred Plus",$N8="Preferred")),"PASS","FAIL")) | Z8: {=IF($A8="","",IFERROR(INDEX(Rubric!$C$26:$C$30,MATCH($J8,Rubric!$B$26:$B$30,1)),0))} | AA8: {=IF($A8="","",IFERROR(INDEX(Rubric!$C$34:$C$37,MATCH($K8,Rubric!$B$34:$B$37,1)),0))} | AB8: {=IF($A8="","",IFERROR(INDEX(Rubric!$C$41:$C$45,MATCH($L8,Rubric!$B$41:$B$45,1)),0))} | AC8: {=IF($A8="","",IFERROR(INDEX(Rubric!$C$49:$C$52,MATCH($N8,Rubric!$B$49:$B$52,0)),0))} | AD8: {=IF($A8="","",IFERROR(INDEX(Rubric!$C$56:$C$59,MATCH($O8,Rubric!$B$56:$B$59,1)),0))} | AE8: {=IF($A8="","",IFERROR(INDEX(Rubric!$C$63:$C$67,MATCH($I8,Rubric!$B$63:$B$67,1)),0))} | AF8: =IF($A8="","",IF($P8="Yes",Rubric!$C$71,0)+IF($R8="Yes",Rubric!$C$72,0)+IF($Q8="Buy 1 Take 1 or better",Rubric!$C$73,0)) | AG8: =IF($A8="","",IFERROR($V8*Rubric!$C$77,0)) | AH8: =IF($A8="","",IF($T8="Yes",Rubric!$C$81,0)+IF($U8="Yes",Rubric!$C$82,0)) | AI8: =IF($A8="","",IF($Y8="FAIL",0,MAX(0,SUM($Z8:$AG8)+$AH8))) | AJ8: {=IF($A8="","",IF($Y8="FAIL","Rejected — failed gate",IFERROR(INDEX(Rubric!$C$86:$C$89,MATCH($AI8,Rubric!$B$86:$B$89,1)),"")))} | AK8: =IF($Y8<>"PASS","",COUNTIFS($Y$4:$Y$63,"PASS",$AI$4:$AI$63,">"&$AI8)+1)
I9: =IF($A9="","",IF($H9=0,0,1-$G9/$H9)) | Y9: =IF($A9="","",IF(AND($J9>=Rubric!$B$5,$K9>=Rubric!$B$6,$L9>=Rubric!$B$7,$S9=Rubric!$B$8,OR($N9="Shopee Mall",$N9="Preferred Plus",$N9="Preferred")),"PASS","FAIL")) | Z9: {=IF($A9="","",IFERROR(INDEX(Rubric!$C$26:$C$30,MATCH($J9,Rubric!$B$26:$B$30,1)),0))} | AA9: {=IF($A9="","",IFERROR(INDEX(Rubric!$C$34:$C$37,MATCH($K9,Rubric!$B$34:$B$37,1)),0))} | AB9: {=IF($A9="","",IFERROR(INDEX(Rubric!$C$41:$C$45,MATCH($L9,Rubric!$B$41:$B$45,1)),0))} | AC9: {=IF($A9="","",IFERROR(INDEX(Rubric!$C$49:$C$52,MATCH($N9,Rubric!$B$49:$B$52,0)),0))} | AD9: {=IF($A9="","",IFERROR(INDEX(Rubric!$C$56:$C$59,MATCH($O9,Rubric!$B$56:$B$59,1)),0))} | AE9: {=IF($A9="","",IFERROR(INDEX(Rubric!$C$63:$C$67,MATCH($I9,Rubric!$B$63:$B$67,1)),0))} | AF9: =IF($A9="","",IF($P9="Yes",Rubric!$C$71,0)+IF($R9="Yes",Rubric!$C$72,0)+IF($Q9="Buy 1 Take 1 or better",Rubric!$C$73,0)) | AG9: =IF($A9="","",IFERROR($V9*Rubric!$C$77,0)) | AH9: =IF($A9="","",IF($T9="Yes",Rubric!$C$81,0)+IF($U9="Yes",Rubric!$C$82,0)) | AI9: =IF($A9="","",IF($Y9="FAIL",0,MAX(0,SUM($Z9:$AG9)+$AH9))) | AJ9: {=IF($A9="","",IF($Y9="FAIL","Rejected — failed gate",IFERROR(INDEX(Rubric!$C$86:$C$89,MATCH($AI9,Rubric!$B$86:$B$89,1)),"")))} | AK9: =IF($Y9<>"PASS","",COUNTIFS($Y$4:$Y$63,"PASS",$AI$4:$AI$63,">"&$AI9)+1)
I10: =IF($A10="","",IF($H10=0,0,1-$G10/$H10)) | Y10: =IF($A10="","",IF(AND($J10>=Rubric!$B$5,$K10>=Rubric!$B$6,$L10>=Rubric!$B$7,$S10=Rubric!$B$8,OR($N10="Shopee Mall",$N10="Preferred Plus",$N10="Preferred")),"PASS","FAIL")) | Z10: {=IF($A10="","",IFERROR(INDEX(Rubric!$C$26:$C$30,MATCH($J10,Rubric!$B$26:$B$30,1)),0))} | AA10: {=IF($A10="","",IFERROR(INDEX(Rubric!$C$34:$C$37,MATCH($K10,Rubric!$B$34:$B$37,1)),0))} | AB10: {=IF($A10="","",IFERROR(INDEX(Rubric!$C$41:$C$45,MATCH($L10,Rubric!$B$41:$B$45,1)),0))} | AC10: {=IF($A10="","",IFERROR(INDEX(Rubric!$C$49:$C$52,MATCH($N10,Rubric!$B$49:$B$52,0)),0))} | AD10: {=IF($A10="","",IFERROR(INDEX(Rubric!$C$56:$C$59,MATCH($O10,Rubric!$B$56:$B$59,1)),0))} | AE10: {=IF($A10="","",IFERROR(INDEX(Rubric!$C$63:$C$67,MATCH($I10,Rubric!$B$63:$B$67,1)),0))} | AF10: =IF($A10="","",IF($P10="Yes",Rubric!$C$71,0)+IF($R10="Yes",Rubric!$C$72,0)+IF($Q10="Buy 1 Take 1 or better",Rubric!$C$73,0)) | AG10: =IF($A10="","",IFERROR($V10*Rubric!$C$77,0)) | AH10: =IF($A10="","",IF($T10="Yes",Rubric!$C$81,0)+IF($U10="Yes",Rubric!$C$82,0)) | AI10: =IF($A10="","",IF($Y10="FAIL",0,MAX(0,SUM($Z10:$AG10)+$AH10))) | AJ10: {=IF($A10="","",IF($Y10="FAIL","Rejected — failed gate",IFERROR(INDEX(Rubric!$C$86:$C$89,MATCH($AI10,Rubric!$B$86:$B$89,1)),"")))} | AK10: =IF($Y10<>"PASS","",COUNTIFS($Y$4:$Y$63,"PASS",$AI$4:$AI$63,">"&$AI10)+1)
I11: =IF($A11="","",IF($H11=0,0,1-$G11/$H11)) | Y11: =IF($A11="","",IF(AND($J11>=Rubric!$B$5,$K11>=Rubric!$B$6,$L11>=Rubric!$B$7,$S11=Rubric!$B$8,OR($N11="Shopee Mall",$N11="Preferred Plus",$N11="Preferred")),"PASS","FAIL")) | Z11: {=IF($A11="","",IFERROR(INDEX(Rubric!$C$26:$C$30,MATCH($J11,Rubric!$B$26:$B$30,1)),0))} | AA11: {=IF($A11="","",IFERROR(INDEX(Rubric!$C$34:$C$37,MATCH($K11,Rubric!$B$34:$B$37,1)),0))} | AB11: {=IF($A11="","",IFERROR(INDEX(Rubric!$C$41:$C$45,MATCH($L11,Rubric!$B$41:$B$45,1)),0))} | AC11: {=IF($A11="","",IFERROR(INDEX(Rubric!$C$49:$C$52,MATCH($N11,Rubric!$B$49:$B$52,0)),0))} | AD11: {=IF($A11="","",IFERROR(INDEX(Rubric!$C$56:$C$59,MATCH($O11,Rubric!$B$56:$B$59,1)),0))} | AE11: {=IF($A11="","",IFERROR(INDEX(Rubric!$C$63:$C$67,MATCH($I11,Rubric!$B$63:$B$67,1)),0))} | AF11: =IF($A11="","",IF($P11="Yes",Rubric!$C$71,0)+IF($R11="Yes",Rubric!$C$72,0)+IF($Q11="Buy 1 Take 1 or better",Rubric!$C$73,0)) | AG11: =IF($A11="","",IFERROR($V11*Rubric!$C$77,0)) | AH11: =IF($A11="","",IF($T11="Yes",Rubric!$C$81,0)+IF($U11="Yes",Rubric!$C$82,0)) | AI11: =IF($A11="","",IF($Y11="FAIL",0,MAX(0,SUM($Z11:$AG11)+$AH11))) | AJ11: {=IF($A11="","",IF($Y11="FAIL","Rejected — failed gate",IFERROR(INDEX(Rubric!$C$86:$C$89,MATCH($AI11,Rubric!$B$86:$B$89,1)),"")))} | AK11: =IF($Y11<>"PASS","",COUNTIFS($Y$4:$Y$63,"PASS",$AI$4:$AI$63,">"&$AI11)+1)
I12: =IF($A12="","",IF($H12=0,0,1-$G12/$H12)) | Y12: =IF($A12="","",IF(AND($J12>=Rubric!$B$5,$K12>=Rubric!$B$6,$L12>=Rubric!$B$7,$S12=Rubric!$B$8,OR($N12="Shopee Mall",$N12="Preferred Plus",$N12="Preferred")),"PASS","FAIL")) | Z12: {=IF($A12="","",IFERROR(INDEX(Rubric!$C$26:$C$30,MATCH($J12,Rubric!$B$26:$B$30,1)),0))} | AA12: {=IF($A12="","",IFERROR(INDEX(Rubric!$C$34:$C$37,MATCH($K12,Rubric!$B$34:$B$37,1)),0))} | AB12: {=IF($A12="","",IFERROR(INDEX(Rubric!$C$41:$C$45,MATCH($L12,Rubric!$B$41:$B$45,1)),0))} | AC12: {=IF($A12="","",IFERROR(INDEX(Rubric!$C$49:$C$52,MATCH($N12,Rubric!$B$49:$B$52,0)),0))} | AD12: {=IF($A12="","",IFERROR(INDEX(Rubric!$C$56:$C$59,MATCH($O12,Rubric!$B$56:$B$59,1)),0))} | AE12: {=IF($A12="","",IFERROR(INDEX(Rubric!$C$63:$C$67,MATCH($I12,Rubric!$B$63:$B$67,1)),0))} | AF12: =IF($A12="","",IF($P12="Yes",Rubric!$C$71,0)+IF($R12="Yes",Rubric!$C$72,0)+IF($Q12="Buy 1 Take 1 or better",Rubric!$C$73,0)) | AG12: =IF($A12="","",IFERROR($V12*Rubric!$C$77,0)) | AH12: =IF($A12="","",IF($T12="Yes",Rubric!$C$81,0)+IF($U12="Yes",Rubric!$C$82,0)) | AI12: =IF($A12="","",IF($Y12="FAIL",0,MAX(0,SUM($Z12:$AG12)+$AH12))) | AJ12: {=IF($A12="","",IF($Y12="FAIL","Rejected — failed gate",IFERROR(INDEX(Rubric!$C$86:$C$89,MATCH($AI12,Rubric!$B$86:$B$89,1)),"")))} | AK12: =IF($Y12<>"PASS","",COUNTIFS($Y$4:$Y$63,"PASS",$AI$4:$AI$63,">"&$AI12)+1)
I13: =IF($A13="","",IF($H13=0,0,1-$G13/$H13)) | Y13: =IF($A13="","",IF(AND($J13>=Rubric!$B$5,$K13>=Rubric!$B$6,$L13>=Rubric!$B$7,$S13=Rubric!$B$8,OR($N13="Shopee Mall",$N13="Preferred Plus",$N13="Preferred")),"PASS","FAIL")) | Z13: {=IF($A13="","",IFERROR(INDEX(Rubric!$C$26:$C$30,MATCH($J13,Rubric!$B$26:$B$30,1)),0))} | AA13: {=IF($A13="","",IFERROR(INDEX(Rubric!$C$34:$C$37,MATCH($K13,Rubric!$B$34:$B$37,1)),0))} | AB13: {=IF($A13="","",IFERROR(INDEX(Rubric!$C$41:$C$45,MATCH($L13,Rubric!$B$41:$B$45,1)),0))} | AC13: {=IF($A13="","",IFERROR(INDEX(Rubric!$C$49:$C$52,MATCH($N13,Rubric!$B$49:$B$52,0)),0))} | AD13: {=IF($A13="","",IFERROR(INDEX(Rubric!$C$56:$C$59,MATCH($O13,Rubric!$B$56:$B$59,1)),0))} | AE13: {=IF($A13="","",IFERROR(INDEX(Rubric!$C$63:$C$67,MATCH($I13,Rubric!$B$63:$B$67,1)),0))} | AF13: =IF($A13="","",IF($P13="Yes",Rubric!$C$71,0)+IF($R13="Yes",Rubric!$C$72,0)+IF($Q13="Buy 1 Take 1 or better",Rubric!$C$73,0)) | AG13: =IF($A13="","",IFERROR($V13*Rubric!$C$77,0)) | AH13: =IF($A13="","",IF($T13="Yes",Rubric!$C$81,0)+IF($U13="Yes",Rubric!$C$82,0)) | AI13: =IF($A13="","",IF($Y13="FAIL",0,MAX(0,SUM($Z13:$AG13)+$AH13))) | AJ13: {=IF($A13="","",IF($Y13="FAIL","Rejected — failed gate",IFERROR(INDEX(Rubric!$C$86:$C$89,MATCH($AI13,Rubric!$B$86:$B$89,1)),"")))} | AK13: =IF($Y13<>"PASS","",COUNTIFS($Y$4:$Y$63,"PASS",$AI$4:$AI$63,">"&$AI13)+1)
I14: =IF($A14="","",IF($H14=0,0,1-$G14/$H14)) | Y14: =IF($A14="","",IF(AND($J14>=Rubric!$B$5,$K14>=Rubric!$B$6,$L14>=Rubric!$B$7,$S14=Rubric!$B$8,OR($N14="Shopee Mall",$N14="Preferred Plus",$N14="Preferred")),"PASS","FAIL")) | Z14: {=IF($A14="","",IFERROR(INDEX(Rubric!$C$26:$C$30,MATCH($J14,Rubric!$B$26:$B$30,1)),0))} | AA14: {=IF($A14="","",IFERROR(INDEX(Rubric!$C$34:$C$37,MATCH($K14,Rubric!$B$34:$B$37,1)),0))} | AB14: {=IF($A14="","",IFERROR(INDEX(Rubric!$C$41:$C$45,MATCH($L14,Rubric!$B$41:$B$45,1)),0))} | AC14: {=IF($A14="","",IFERROR(INDEX(Rubric!$C$49:$C$52,MATCH($N14,Rubric!$B$49:$B$52,0)),0))} | AD14: {=IF($A14="","",IFERROR(INDEX(Rubric!$C$56:$C$59,MATCH($O14,Rubric!$B$56:$B$59,1)),0))} | AE14: {=IF($A14="","",IFERROR(INDEX(Rubric!$C$63:$C$67,MATCH($I14,Rubric!$B$63:$B$67,1)),0))} | AF14: =IF($A14="","",IF($P14="Yes",Rubric!$C$71,0)+IF($R14="Yes",Rubric!$C$72,0)+IF($Q14="Buy 1 Take 1 or better",Rubric!$C$73,0)) | AG14: =IF($A14="","",IFERROR($V14*Rubric!$C$77,0)) | AH14: =IF($A14="","",IF($T14="Yes",Rubric!$C$81,0)+IF($U14="Yes",Rubric!$C$82,0)) | AI14: =IF($A14="","",IF($Y14="FAIL",0,MAX(0,SUM($Z14:$AG14)+$AH14))) | AJ14: {=IF($A14="","",IF($Y14="FAIL","Rejected — failed gate",IFERROR(INDEX(Rubric!$C$86:$C$89,MATCH($AI14,Rubric!$B$86:$B$89,1)),"")))} | AK14: =IF($Y14<>"PASS","",COUNTIFS($Y$4:$Y$63,"PASS",$AI$4:$AI$63,">"&$AI14)+1)
I15: =IF($A15="","",IF($H15=0,0,1-$G15/$H15)) | Y15: =IF($A15="","",IF(AND($J15>=Rubric!$B$5,$K15>=Rubric!$B$6,$L15>=Rubric!$B$7,$S15=Rubric!$B$8,OR($N15="Shopee Mall",$N15="Preferred Plus",$N15="Preferred")),"PASS","FAIL")) | Z15: {=IF($A15="","",IFERROR(INDEX(Rubric!$C$26:$C$30,MATCH($J15,Rubric!$B$26:$B$30,1)),0))} | AA15: {=IF($A15="","",IFERROR(INDEX(Rubric!$C$34:$C$37,MATCH($K15,Rubric!$B$34:$B$37,1)),0))} | AB15: {=IF($A15="","",IFERROR(INDEX(Rubric!$C$41:$C$45,MATCH($L15,Rubric!$B$41:$B$45,1)),0))} | AC15: {=IF($A15="","",IFERROR(INDEX(Rubric!$C$49:$C$52,MATCH($N15,Rubric!$B$49:$B$52,0)),0))} | AD15: {=IF($A15="","",IFERROR(INDEX(Rubric!$C$56:$C$59,MATCH($O15,Rubric!$B$56:$B$59,1)),0))} | AE15: {=IF($A15="","",IFERROR(INDEX(Rubric!$C$63:$C$67,MATCH($I15,Rubric!$B$63:$B$67,1)),0))} | AF15: =IF($A15="","",IF($P15="Yes",Rubric!$C$71,0)+IF($R15="Yes",Rubric!$C$72,0)+IF($Q15="Buy 1 Take 1 or better",Rubric!$C$73,0)) | AG15: =IF($A15="","",IFERROR($V15*Rubric!$C$77,0)) | AH15: =IF($A15="","",IF($T15="Yes",Rubric!$C$81,0)+IF($U15="Yes",Rubric!$C$82,0)) | AI15: =IF($A15="","",IF($Y15="FAIL",0,MAX(0,SUM($Z15:$AG15)+$AH15))) | AJ15: {=IF($A15="","",IF($Y15="FAIL","Rejected — failed gate",IFERROR(INDEX(Rubric!$C$86:$C$89,MATCH($AI15,Rubric!$B$86:$B$89,1)),"")))} | AK15: =IF($Y15<>"PASS","",COUNTIFS($Y$4:$Y$63,"PASS",$AI$4:$AI$63,">"&$AI15)+1)
I16: =IF($A16="","",IF($H16=0,0,1-$G16/$H16)) | Y16: =IF($A16="","",IF(AND($J16>=Rubric!$B$5,$K16>=Rubric!$B$6,$L16>=Rubric!$B$7,$S16=Rubric!$B$8,OR($N16="Shopee Mall",$N16="Preferred Plus",$N16="Preferred")),"PASS","FAIL")) | Z16: {=IF($A16="","",IFERROR(INDEX(Rubric!$C$26:$C$30,MATCH($J16,Rubric!$B$26:$B$30,1)),0))} | AA16: {=IF($A16="","",IFERROR(INDEX(Rubric!$C$34:$C$37,MATCH($K16,Rubric!$B$34:$B$37,1)),0))} | AB16: {=IF($A16="","",IFERROR(INDEX(Rubric!$C$41:$C$45,MATCH($L16,Rubric!$B$41:$B$45,1)),0))} | AC16: {=IF($A16="","",IFERROR(INDEX(Rubric!$C$49:$C$52,MATCH($N16,Rubric!$B$49:$B$52,0)),0))} | AD16: {=IF($A16="","",IFERROR(INDEX(Rubric!$C$56:$C$59,MATCH($O16,Rubric!$B$56:$B$59,1)),0))} | AE16: {=IF($A16="","",IFERROR(INDEX(Rubric!$C$63:$C$67,MATCH($I16,Rubric!$B$63:$B$67,1)),0))} | AF16: =IF($A16="","",IF($P16="Yes",Rubric!$C$71,0)+IF($R16="Yes",Rubric!$C$72,0)+IF($Q16="Buy 1 Take 1 or better",Rubric!$C$73,0)) | AG16: =IF($A16="","",IFERROR($V16*Rubric!$C$77,0)) | AH16: =IF($A16="","",IF($T16="Yes",Rubric!$C$81,0)+IF($U16="Yes",Rubric!$C$82,0)) | AI16: =IF($A16="","",IF($Y16="FAIL",0,MAX(0,SUM($Z16:$AG16)+$AH16))) | AJ16: {=IF($A16="","",IF($Y16="FAIL","Rejected — failed gate",IFERROR(INDEX(Rubric!$C$86:$C$89,MATCH($AI16,Rubric!$B$86:$B$89,1)),"")))} | AK16: =IF($Y16<>"PASS","",COUNTIFS($Y$4:$Y$63,"PASS",$AI$4:$AI$63,">"&$AI16)+1)
... I63: =IF($A63="","",IF($H63=0,0,1-$G63/$H63)) | Y63: =IF($A63="","",IF(AND($J63>=Rubric!$B$5,$K63>=Rubric!$B$6,$L63>=Rubric!$B$7,$S63=Rubric!$B$8,OR($N63="Shopee Mall",$N63="Preferred Plus",$N63="Preferred")),"PASS","FAIL")) | Z63: {=IF($A63="","",IFERROR(INDEX(Rubric!$C$26:$C$30,MATCH($J63,Rubric!$B$26:$B$30,1)),0))} | AA63: {=IF($A63="","",IFERROR(INDEX(Rubric!$C$34:$C$37,MATCH($K63,Rubric!$B$34:$B$37,1)),0))} | AB63: {=IF($A63="","",IFERROR(INDEX(Rubric!$C$41:$C$45,MATCH($L63,Rubric!$B$41:$B$45,1)),0))} | AC63: {=IF($A63="","",IFERROR(INDEX(Rubric!$C$49:$C$52,MATCH($N63,Rubric!$B$49:$B$52,0)),0))} | AD63: {=IF($A63="","",IFERROR(INDEX(Rubric!$C$56:$C$59,MATCH($O63,Rubric!$B$56:$B$59,1)),0))} | AE63: {=IF($A63="","",IFERROR(INDEX(Rubric!$C$63:$C$67,MATCH($I63,Rubric!$B$63:$B$67,1)),0))} | AF63: =IF($A63="","",IF($P63="Yes",Rubric!$C$71,0)+IF($R63="Yes",Rubric!$C$72,0)+IF($Q63="Buy 1 Take 1 or better",Rubric!$C$73,0)) | AG63: =IF($A63="","",IFERROR($V63*Rubric!$C$77,0)) | AH63: =IF($A63="","",IF($T63="Yes",Rubric!$C$81,0)+IF($U63="Yes",Rubric!$C$82,0)) | AI63: =IF($A63="","",IF($Y63="FAIL",0,MAX(0,SUM($Z63:$AG63)+$AH63))) | AJ63: {=IF($A63="","",IF($Y63="FAIL","Rejected — failed gate",IFERROR(INDEX(Rubric!$C$86:$C$89,MATCH($AI63,Rubric!$B$86:$B$89,1)),"")))} | AK63: =IF($Y63<>"PASS","",COUNTIFS($Y$4:$Y$63,"PASS",$AI$4:$AI$63,">"&$AI63)+1)

Sheet Content
A1: Listing Copy — product names pull from the Tracker automatically
A2: Short title hard-capped at 60 characters — column D flags anything over.
A3: Product Name (auto) | B3: Short Title (max 60 chars) | C3: Chars | D3: Title Check | E3: Short Description | F3: Selling Point 1 | G3: Selling Point 2 | H3: Selling Point 3 | I3: Selling Point 4 | J3: Selling Point 5 | K3: Call to Action | L3: Images Ready (Main / Lifestyle / Close-up) | M3: Collection(s) | N3: Status
A4: =IF(Tracker!$A4="","",Tracker!$A4) -> [EXAMPLE — delete this row] 20W USB-C Fast Charger | B4: 20W USB-C Fast Charger with Cable Support | C4: =IF($B4="","",LEN($B4)) -> 41 | D4: =IF($B4="","",IF(LEN($B4)<=60,"OK","OVER LIMIT")) -> OK | E4: Charge your phone in a fraction of the time with this compact 20W USB-C charger. Built for commuters and desk setups where every minute counts. | F4: 20W PD fast charging | G4: Pocket-sized build | H4: Safe-charge protection | I4: Works with iPhone and Android | J4: Strong value under ₱300 | K4: Shop Now | L4: Main + Lifestyle | M4: Electronics; Best Sellers; Under ₱499 | N4: Draft
A5: =IF(Tracker!$A5="","",Tracker!$A5) | C5: =IF($B5="","",LEN($B5)) | D5: =IF($B5="","",IF(LEN($B5)<=60,"OK","OVER LIMIT"))
A6: =IF(Tracker!$A6="","",Tracker!$A6) | C6: =IF($B6="","",LEN($B6)) | D6: =IF($B6="","",IF(LEN($B6)<=60,"OK","OVER LIMIT"))
A7: =IF(Tracker!$A7="","",Tracker!$A7) | C7: =IF($B7="","",LEN($B7)) | D7: =IF($B7="","",IF(LEN($B7)<=60,"OK","OVER LIMIT"))
A8: =IF(Tracker!$A8="","",Tracker!$A8) | C8: =IF($B8="","",LEN($B8)) | D8: =IF($B8="","",IF(LEN($B8)<=60,"OK","OVER LIMIT"))
A9: =IF(Tracker!$A9="","",Tracker!$A9) | C9: =IF($B9="","",LEN($B9)) | D9: =IF($B9="","",IF(LEN($B9)<=60,"OK","OVER LIMIT"))
A10: =IF(Tracker!$A10="","",Tracker!$A10) | C10: =IF($B10="","",LEN($B10)) | D10: =IF($B10="","",IF(LEN($B10)<=60,"OK","OVER LIMIT"))
A11: =IF(Tracker!$A11="","",Tracker!$A11) | C11: =IF($B11="","",LEN($B11)) | D11: =IF($B11="","",IF(LEN($B11)<=60,"OK","OVER LIMIT"))
A12: =IF(Tracker!$A12="","",Tracker!$A12) | C12: =IF($B12="","",LEN($B12)) | D12: =IF($B12="","",IF(LEN($B12)<=60,"OK","OVER LIMIT"))
A13: =IF(Tracker!$A13="","",Tracker!$A13) | C13: =IF($B13="","",LEN($B13)) | D13: =IF($B13="","",IF(LEN($B13)<=60,"OK","OVER LIMIT"))
A14: =IF(Tracker!$A14="","",Tracker!$A14) | C14: =IF($B14="","",LEN($B14)) | D14: =IF($B14="","",IF(LEN($B14)<=60,"OK","OVER LIMIT"))
A15: =IF(Tracker!$A15="","",Tracker!$A15) | C15: =IF($B15="","",LEN($B15)) | D15: =IF($B15="","",IF(LEN($B15)<=60,"OK","OVER LIMIT"))
A16: =IF(Tracker!$A16="","",Tracker!$A16) | C16: =IF($B16="","",LEN($B16)) | D16: =IF($B16="","",IF(LEN($B16)<=60,"OK","OVER LIMIT"))
... A63: =IF(Tracker!$A63="","",Tracker!$A63) | C63: =IF($B63="","",LEN($B63)) | D63: =IF($B63="","",IF(LEN($B63)<=60,"OK","OVER LIMIT"))

Sheet Collections
A1: Collections — live count of gate-passing products
A3: Collection | B3: Assignment rule | C3: Products
A4: Best Sellers | B4: 10,000+ units sold | C4: =COUNTIFS(Tracker!$Y$4:$Y$63,"PASS",Tracker!$J$4:$J$63,">=10000") -> 1
A5: Trending Today | B5: Hand-picked — tag in Content column M | C5: =COUNTIF(Content!$M$4:$M$63,"*Trending Today*") -> 0
A6: Electronics | B6: Category = Electronics | C6: =COUNTIFS(Tracker!$Y$4:$Y$63,"PASS",Tracker!$D$4:$D$63,"Electronics") -> 1
A7: Home Essentials | B7: Category = Home & Living | C7: =COUNTIFS(Tracker!$Y$4:$Y$63,"PASS",Tracker!$D$4:$D$63,"Home & Living") -> 0
A8: Beauty Picks | B8: Category = Health & Beauty | C8: =COUNTIFS(Tracker!$Y$4:$Y$63,"PASS",Tracker!$D$4:$D$63,"Health & Beauty") -> 0
A9: Kitchen Finds | B9: Subcategory contains 'Kitchen' | C9: =COUNTIFS(Tracker!$Y$4:$Y$63,"PASS",Tracker!$E$4:$E$63,"*Kitchen*") -> 0
A10: Pet Essentials | B10: Category = Pet Supplies | C10: =COUNTIFS(Tracker!$Y$4:$Y$63,"PASS",Tracker!$D$4:$D$63,"Pet Supplies") -> 0
A11: Budget Deals | B11: Discount 30% or more | C11: =COUNTIFS(Tracker!$Y$4:$Y$63,"PASS",Tracker!$I$4:$I$63,">=0.3") -> 1
A12: Under ₱199 | B12: Current price ≤ ₱199 | C12: =COUNTIFS(Tracker!$Y$4:$Y$63,"PASS",Tracker!$G$4:$G$63,"<=199") -> 0
A13: Under ₱499 | B13: Current price ₱200–₱499 | C13: =COUNTIFS(Tracker!$Y$4:$Y$63,"PASS",Tracker!$G$4:$G$63,">199",Tracker!$G$4:$G$63,"<=499") -> 1
A14: Premium Picks | B14: Price over ₱999 and score ≥ 80 | C14: =COUNTIFS(Tracker!$Y$4:$Y$63,"PASS",Tracker!$G$4:$G$63,">999",Tracker!$AI$4:$AI$63,">=80") -> 0
A16: Counts include the example row until you delete Tracker row 4.
A17: A collection showing 0–2 products is too thin to publish — go research that category next.
